2022-11-15 19:56:52,933 DEBUG    root            Loaded Command Group: ['gcloud', 'auth']
2022-11-15 19:56:52,933 DEBUG    root            Loaded Command Group: ['gcloud', 'auth']
2022-11-15 19:56:52,936 DEBUG    root            Loaded Command Group: ['gcloud', 'auth', 'application_default']
2022-11-15 19:56:52,939 DEBUG    root            Loaded Command Group: ['gcloud', 'auth', 'application-default', 'print_access_token']
2022-11-15 19:56:52,940 DEBUG    root            Loaded Command Group: ['gcloud', 'auth', 'list']
2022-11-15 19:56:52,941 DEBUG    root            Running [gcloud.auth.application-default.print-access-token] with arguments: [--quiet: "True", --verbosity: "warning"]
2022-11-15 19:56:52,942 DEBUG    google.auth.transport._http_client Making request: GET http://169.254.169.254
2022-11-15 19:56:52,942 DEBUG    root            Running [gcloud.auth.list] with arguments: [--filter: "status=ACTIVE", --format: "value(account)", --quiet: "True", --verbosity: "warning"]
2022-11-15 19:56:52,953 INFO     root            Display format: "    table[title='Credentialed Accounts'](
        status.yesno(yes='*', no=''):label=ACTIVE,
        account
    ) value(account)"
2022-11-15 19:56:52,953 WARNING  root            The following filter keys were not present in any resource : status
2022-11-15 19:56:55,943 WARNING  google.auth.compute_engine._metadata Compute Engine Metadata server unavailable on attempt 1 of 3. Reason: timed out
2022-11-15 19:56:55,944 DEBUG    google.auth.transport._http_client Making request: GET http://169.254.169.254
2022-11-15 19:56:58,944 WARNING  google.auth.compute_engine._metadata Compute Engine Metadata server unavailable on attempt 2 of 3. Reason: timed out
2022-11-15 19:56:58,945 DEBUG    google.auth.transport._http_client Making request: GET http://169.254.169.254
2022-11-15 19:56:58,948 WARNING  google.auth.compute_engine._metadata Compute Engine Metadata server unavailable on attempt 3 of 3. Reason: [Errno 64] Host is down
2022-11-15 19:56:58,948 DEBUG    root            Could not automatically determine credentials. Please set GOOGLE_APPLICATION_CREDENTIALS or explicitly create credentials and re-run the application. For more information, please see https://cloud.google.com/docs/authentication/getting-started
Traceback (most recent call last):
  File "/Users/satyampatel/Library/Application Support/cloud-code/installer/google-cloud-sdk/lib/surface/auth/application_default/print_access_token.py", line 106, in Run
    creds, _ = c_creds.GetGoogleAuthDefault().default(
  File "/Users/satyampatel/Library/Application Support/cloud-code/installer/google-cloud-sdk/lib/third_party/google/auth/_default.py", line 643, in default
    raise exceptions.DefaultCredentialsError(_HELP_MESSAGE)
google.auth.exceptions.DefaultCredentialsError: Could not automatically determine credentials. Please set GOOGLE_APPLICATION_CREDENTIALS or explicitly create credentials and re-run the application. For more information, please see https://cloud.google.com/docs/authentication/getting-started
2022-11-15 19:56:58,949 DEBUG    root            (gcloud.auth.application-default.print-access-token) Could not automatically determine credentials. Please set GOOGLE_APPLICATION_CREDENTIALS or explicitly create credentials and re-run the application. For more information, please see https://cloud.google.com/docs/authentication/getting-started
Traceback (most recent call last):
  File "/Users/satyampatel/Library/Application Support/cloud-code/installer/google-cloud-sdk/lib/surface/auth/application_default/print_access_token.py", line 106, in Run
    creds, _ = c_creds.GetGoogleAuthDefault().default(
  File "/Users/satyampatel/Library/Application Support/cloud-code/installer/google-cloud-sdk/lib/third_party/google/auth/_default.py", line 643, in default
    raise exceptions.DefaultCredentialsError(_HELP_MESSAGE)
google.auth.exceptions.DefaultCredentialsError: Could not automatically determine credentials. Please set GOOGLE_APPLICATION_CREDENTIALS or explicitly create credentials and re-run the application. For more information, please see https://cloud.google.com/docs/authentication/getting-started

During handling of the above exception, another exception occurred:

Traceback (most recent call last):
  File "/Users/satyampatel/Library/Application Support/cloud-code/installer/google-cloud-sdk/lib/googlecloudsdk/calliope/cli.py", line 987, in Execute
    resources = calliope_command.Run(cli=self, args=args)
  File "/Users/satyampatel/Library/Application Support/cloud-code/installer/google-cloud-sdk/lib/googlecloudsdk/calliope/backend.py", line 807, in Run
    resources = command_instance.Run(args)
  File "/Users/satyampatel/Library/Application Support/cloud-code/installer/google-cloud-sdk/lib/surface/auth/application_default/print_access_token.py", line 110, in Run
    raise c_exc.ToolException(six.text_type(e))
googlecloudsdk.calliope.exceptions.ToolException: Could not automatically determine credentials. Please set GOOGLE_APPLICATION_CREDENTIALS or explicitly create credentials and re-run the application. For more information, please see https://cloud.google.com/docs/authentication/getting-started
2022-11-15 19:56:58,950 ERROR    root            (gcloud.auth.application-default.print-access-token) Could not automatically determine credentials. Please set GOOGLE_APPLICATION_CREDENTIALS or explicitly create credentials and re-run the application. For more information, please see https://cloud.google.com/docs/authentication/getting-started
