2022-11-20 16:58:19,568 DEBUG    root            Loaded Command Group: ['gcloud', 'auth']
2022-11-20 16:58:19,568 DEBUG    root            Loaded Command Group: ['gcloud', 'auth']
2022-11-20 16:58:19,572 DEBUG    root            Loaded Command Group: ['gcloud', 'auth', 'application_default']
2022-11-20 16:58:19,575 DEBUG    root            Loaded Command Group: ['gcloud', 'auth', 'application-default', 'print_access_token']
2022-11-20 16:58:19,575 DEBUG    root            Loaded Command Group: ['gcloud', 'auth', 'list']
2022-11-20 16:58:19,578 DEBUG    root            Running [gcloud.auth.application-default.print-access-token] with arguments: [--quiet: "True", --verbosity: "warning"]
2022-11-20 16:58:19,578 DEBUG    root            Running [gcloud.auth.list] with arguments: [--filter: "status=ACTIVE", --format: "value(account)", --quiet: "True", --verbosity: "warning"]
2022-11-20 16:58:19,578 DEBUG    google.auth.transport._http_client Making request: GET http://169.254.169.254
2022-11-20 16:58:19,587 WARNING  google.auth.compute_engine._metadata Compute Engine Metadata server unavailable on attempt 1 of 3. Reason: [Errno 51] Network is unreachable
2022-11-20 16:58:19,587 DEBUG    google.auth.transport._http_client Making request: GET http://169.254.169.254
2022-11-20 16:58:19,589 WARNING  google.auth.compute_engine._metadata Compute Engine Metadata server unavailable on attempt 2 of 3. Reason: [Errno 51] Network is unreachable
2022-11-20 16:58:19,590 DEBUG    google.auth.transport._http_client Making request: GET http://169.254.169.254
2022-11-20 16:58:19,592 WARNING  google.auth.compute_engine._metadata Compute Engine Metadata server unavailable on attempt 3 of 3. Reason: [Errno 51] Network is unreachable
2022-11-20 16:58:19,592 DEBUG    root            Could not automatically determine credentials. Please set GOOGLE_APPLICATION_CREDENTIALS or explicitly create credentials and re-run the application. For more information, please see https://cloud.google.com/docs/authentication/getting-started
Traceback (most recent call last):
  File "/Users/satyampatel/Library/Application Support/cloud-code/installer/google-cloud-sdk/lib/surface/auth/application_default/print_access_token.py", line 106, in Run
    creds, _ = c_creds.GetGoogleAuthDefault().default(
  File "/Users/satyampatel/Library/Application Support/cloud-code/installer/google-cloud-sdk/lib/third_party/google/auth/_default.py", line 643, in default
    raise exceptions.DefaultCredentialsError(_HELP_MESSAGE)
google.auth.exceptions.DefaultCredentialsError: Could not automatically determine credentials. Please set GOOGLE_APPLICATION_CREDENTIALS or explicitly create credentials and re-run the application. For more information, please see https://cloud.google.com/docs/authentication/getting-started
2022-11-20 16:58:19,594 DEBUG    root            (gcloud.auth.application-default.print-access-token) Could not automatically determine credentials. Please set GOOGLE_APPLICATION_CREDENTIALS or explicitly create credentials and re-run the application. For more information, please see https://cloud.google.com/docs/authentication/getting-started
Traceback (most recent call last):
  File "/Users/satyampatel/Library/Application Support/cloud-code/installer/google-cloud-sdk/lib/surface/auth/application_default/print_access_token.py", line 106, in Run
    creds, _ = c_creds.GetGoogleAuthDefault().default(
  File "/Users/satyampatel/Library/Application Support/cloud-code/installer/google-cloud-sdk/lib/third_party/google/auth/_default.py", line 643, in default
    raise exceptions.DefaultCredentialsError(_HELP_MESSAGE)
google.auth.exceptions.DefaultCredentialsError: Could not automatically determine credentials. Please set GOOGLE_APPLICATION_CREDENTIALS or explicitly create credentials and re-run the application. For more information, please see https://cloud.google.com/docs/authentication/getting-started

During handling of the above exception, another exception occurred:

Traceback (most recent call last):
  File "/Users/satyampatel/Library/Application Support/cloud-code/installer/google-cloud-sdk/lib/googlecloudsdk/calliope/cli.py", line 987, in Execute
    resources = calliope_command.Run(cli=self, args=args)
  File "/Users/satyampatel/Library/Application Support/cloud-code/installer/google-cloud-sdk/lib/googlecloudsdk/calliope/backend.py", line 807, in Run
    resources = command_instance.Run(args)
  File "/Users/satyampatel/Library/Application Support/cloud-code/installer/google-cloud-sdk/lib/surface/auth/application_default/print_access_token.py", line 110, in Run
    raise c_exc.ToolException(six.text_type(e))
googlecloudsdk.calliope.exceptions.ToolException: Could not automatically determine credentials. Please set GOOGLE_APPLICATION_CREDENTIALS or explicitly create credentials and re-run the application. For more information, please see https://cloud.google.com/docs/authentication/getting-started
2022-11-20 16:58:19,597 ERROR    root            (gcloud.auth.application-default.print-access-token) Could not automatically determine credentials. Please set GOOGLE_APPLICATION_CREDENTIALS or explicitly create credentials and re-run the application. For more information, please see https://cloud.google.com/docs/authentication/getting-started
2022-11-20 16:58:19,597 INFO     root            Display format: "    table[title='Credentialed Accounts'](
        status.yesno(yes='*', no=''):label=ACTIVE,
        account
    ) value(account)"
2022-11-20 16:58:19,598 WARNING  root            The following filter keys were not present in any resource : status
2022-11-20 16:58:19,600 DEBUG    root            Checking for updates...
2022-11-20 16:58:19,622 DEBUG    urllib3.connectionpool Starting new HTTPS connection (1): dl.google.com:443
2022-11-20 16:58:19,623 DEBUG    root            Failed to perform update check.
Traceback (most recent call last):
  File "/Users/satyampatel/Library/Application Support/cloud-code/installer/google-cloud-sdk/lib/third_party/urllib3/connection.py", line 174, in _new_conn
    conn = connection.create_connection(
  File "/Users/satyampatel/Library/Application Support/cloud-code/installer/google-cloud-sdk/lib/third_party/urllib3/util/connection.py", line 72, in create_connection
    for res in socket.getaddrinfo(host, port, family, socket.SOCK_STREAM):
  File "/usr/local/Cellar/python@3.10/3.10.8/Frameworks/Python.framework/Versions/3.10/lib/python3.10/socket.py", line 955, in getaddrinfo
    for res in _socket.getaddrinfo(host, port, family, type, proto, flags):
socket.gaierror: [Errno 8] nodename nor servname provided, or not known

During handling of the above exception, another exception occurred:

Traceback (most recent call last):
  File "/Users/satyampatel/Library/Application Support/cloud-code/installer/google-cloud-sdk/lib/third_party/urllib3/connectionpool.py", line 703, in urlopen
    httplib_response = self._make_request(
  File "/Users/satyampatel/Library/Application Support/cloud-code/installer/google-cloud-sdk/lib/third_party/urllib3/connectionpool.py", line 386, in _make_request
    self._validate_conn(conn)
  File "/Users/satyampatel/Library/Application Support/cloud-code/installer/google-cloud-sdk/lib/third_party/urllib3/connectionpool.py", line 1040, in _validate_conn
    conn.connect()
  File "/Users/satyampatel/Library/Application Support/cloud-code/installer/google-cloud-sdk/lib/third_party/urllib3/connection.py", line 358, in connect
    self.sock = conn = self._new_conn()
  File "/Users/satyampatel/Library/Application Support/cloud-code/installer/google-cloud-sdk/lib/third_party/urllib3/connection.py", line 186, in _new_conn
    raise NewConnectionError(
urllib3.exceptions.NewConnectionError: <urllib3.connection.HTTPSConnection object at 0x1128bcbe0>: Failed to establish a new connection: [Errno 8] nodename nor servname provided, or not known

During handling of the above exception, another exception occurred:

Traceback (most recent call last):
  File "/Users/satyampatel/Library/Application Support/cloud-code/installer/google-cloud-sdk/lib/third_party/requests/adapters.py", line 439, in send
    resp = conn.urlopen(
  File "/Users/satyampatel/Library/Application Support/cloud-code/installer/google-cloud-sdk/lib/third_party/urllib3/connectionpool.py", line 785, in urlopen
    retries = retries.increment(
  File "/Users/satyampatel/Library/Application Support/cloud-code/installer/google-cloud-sdk/lib/third_party/urllib3/util/retry.py", line 592, in increment
    raise MaxRetryError(_pool, url, error or ResponseError(cause))
urllib3.exceptions.MaxRetryError: HTTPSConnectionPool(host='dl.google.com', port=443): Max retries exceeded with url: /dl/cloudsdk/channels/rapid/components-2.json (Caused by NewConnectionError('<urllib3.connection.HTTPSConnection object at 0x1128bcbe0>: Failed to establish a new connection: [Errno 8] nodename nor servname provided, or not known'))

During handling of the above exception, another exception occurred:

Traceback (most recent call last):
  File "/Users/satyampatel/Library/Application Support/cloud-code/installer/google-cloud-sdk/lib/googlecloudsdk/gcloud_main.py", line 61, in UpdateCheck
    update_manager.UpdateManager.PerformUpdateCheck(command_path=command_path)
  File "/Users/satyampatel/Library/Application Support/cloud-code/installer/google-cloud-sdk/lib/googlecloudsdk/core/updater/update_manager.py", line 304, in PerformUpdateCheck
    manager._PerformUpdateCheck(command_path, force=force)
  File "/Users/satyampatel/Library/Application Support/cloud-code/installer/google-cloud-sdk/lib/googlecloudsdk/core/updater/update_manager.py", line 738, in _PerformUpdateCheck
    (_, diff) = self._GetStateAndDiff(
  File "/Users/satyampatel/Library/Application Support/cloud-code/installer/google-cloud-sdk/lib/googlecloudsdk/core/updater/update_manager.py", line 692, in _GetStateAndDiff
    latest_snapshot = self._GetLatestSnapshot(version=version,
  File "/Users/satyampatel/Library/Application Support/cloud-code/installer/google-cloud-sdk/lib/googlecloudsdk/core/updater/update_manager.py", line 675, in _GetLatestSnapshot
    return snapshots.ComponentSnapshot.FromURLs(
  File "/Users/satyampatel/Library/Application Support/cloud-code/installer/google-cloud-sdk/lib/googlecloudsdk/core/updater/snapshots.py", line 175, in FromURLs
    data = [
  File "/Users/satyampatel/Library/Application Support/cloud-code/installer/google-cloud-sdk/lib/googlecloudsdk/core/updater/snapshots.py", line 176, in <listcomp>
    (ComponentSnapshot._DictFromURL(
  File "/Users/satyampatel/Library/Application Support/cloud-code/installer/google-cloud-sdk/lib/googlecloudsdk/core/updater/snapshots.py", line 200, in _DictFromURL
    response = installers.MakeRequest(url, command_path)
  File "/Users/satyampatel/Library/Application Support/cloud-code/installer/google-cloud-sdk/lib/googlecloudsdk/core/updater/installers.py", line 114, in MakeRequest
    return _RawRequest(url, headers=headers, timeout=timeout)
  File "/Users/satyampatel/Library/Application Support/cloud-code/installer/google-cloud-sdk/lib/googlecloudsdk/core/updater/installers.py", line 162, in _RawRequest
    return retryer.RetryOnException(
  File "/Users/satyampatel/Library/Application Support/cloud-code/installer/google-cloud-sdk/lib/googlecloudsdk/core/util/retry.py", line 201, in RetryOnException
    exceptions.reraise(exc_info[1], tb=exc_info[2])
  File "/Users/satyampatel/Library/Application Support/cloud-code/installer/google-cloud-sdk/lib/googlecloudsdk/core/exceptions.py", line 146, in reraise
    six.reraise(type(exc_value), exc_value, tb)
  File "/Users/satyampatel/Library/Application Support/cloud-code/installer/google-cloud-sdk/lib/third_party/six/__init__.py", line 693, in reraise
    raise value
  File "/Users/satyampatel/Library/Application Support/cloud-code/installer/google-cloud-sdk/lib/googlecloudsdk/core/util/retry.py", line 182, in TryFunc
    return func(*args, **kwargs), None
  File "/Users/satyampatel/Library/Application Support/cloud-code/installer/google-cloud-sdk/lib/googlecloudsdk/core/updater/installers.py", line 192, in _ExecuteRequestAndRaiseExceptions
    response = requests_session.get(
  File "/Users/satyampatel/Library/Application Support/cloud-code/installer/google-cloud-sdk/lib/third_party/requests/sessions.py", line 555, in get
    return self.request('GET', url, **kwargs)
  File "/Users/satyampatel/Library/Application Support/cloud-code/installer/google-cloud-sdk/lib/googlecloudsdk/core/transport.py", line 251, in WrappedRequest
    response = orig_request(*modified_args, **modified_kwargs)
  File "/Users/satyampatel/Library/Application Support/cloud-code/installer/google-cloud-sdk/lib/googlecloudsdk/core/requests.py", line 246, in WrappedRequest
    return orig_request_method(*args, **kwargs)
  File "/Users/satyampatel/Library/Application Support/cloud-code/installer/google-cloud-sdk/lib/third_party/requests/sessions.py", line 542, in request
    resp = self.send(prep, **send_kwargs)
  File "/Users/satyampatel/Library/Application Support/cloud-code/installer/google-cloud-sdk/lib/third_party/requests/sessions.py", line 655, in send
    r = adapter.send(request, **kwargs)
  File "/Users/satyampatel/Library/Application Support/cloud-code/installer/google-cloud-sdk/lib/third_party/requests/adapters.py", line 516, in send
    raise ConnectionError(e, request=request)
requests.exceptions.ConnectionError: HTTPSConnectionPool(host='dl.google.com', port=443): Max retries exceeded with url: /dl/cloudsdk/channels/rapid/components-2.json (Caused by NewConnectionError('<urllib3.connection.HTTPSConnection object at 0x1128bcbe0>: Failed to establish a new connection: [Errno 8] nodename nor servname provided, or not known'))
